ControlFlow Exceptions
======================

.. testsetup::

    from pathlib import Path
    Path('/tmp/myfile.txt').unlink(missing_ok=True)


Rationale
---------
* Used when error occurs
* You can catch exception and handles erroneous situation
* Exception example situations:

    * File does not exists
    * No permissions to read file
    * Function argument is invalid type (ie. ``int('one')``)
    * Value is incorrect (ie. negative Kelvin temperature)
    * Network or database connection could not be established


Most Common Exceptions
----------------------
``AttributeError`` - Attribute reference or assignment fails:

    >>> name = 'Jan'
    >>> name.append('Twardowski')
    Traceback (most recent call last):
    AttributeError: 'str' object has no attribute 'append'

``ImportError``, ``ModuleNotFoundError`` - Module could not be located:

    >>> import math
    >>> import match
    Traceback (most recent call last):
    ModuleNotFoundError: No module named 'match'

``IndexError`` - Sequence subscript is out of range:

    >>> DATA = ['a', 'b', 'c']
    >>> DATA[100]
    Traceback (most recent call last):
    IndexError: list index out of range

``KeyError`` - Dictionary key is not found:

    >>> DATA = {'a': 1, 'b': 2}
    >>> DATA['x']
    Traceback (most recent call last):
    KeyError: 'x'

``NameError`` - Local or global name is not found:

    >>> print(firstname)
    Traceback (most recent call last):
    NameError: name 'firstname' is not defined

``SyntaxError`` - Parser encounters a syntax error:

    >>> if True
    ...    print('Yes')
    Traceback (most recent call last):
    SyntaxError: invalid syntax

``IndentationError`` - Syntax errors related to incorrect indentation:

    >>> if True:
    ...   print('Hello!')
    ...    print('My name...')
    ...   print('José Jiménez')
    Traceback (most recent call last):
    IndentationError: unexpected indent

``TypeError`` - Operation or function is applied to an object of inappropriate type:

    >>> 42 + 'a'
    Traceback (most recent call last):
    TypeError: unsupported operand type(s) for +: 'int' and 'str'

    >>> 'a' + 42
    Traceback (most recent call last):
    TypeError: can only concatenate str (not "int") to str

    >>> a = ['a', 'b', 'c']
    >>> a[1.5]
    Traceback (most recent call last):
    TypeError: list indices must be integers or slices, not float

    >>> a, b = 1
    Traceback (most recent call last):
    TypeError: cannot unpack non-iterable int object

``ValueError`` Argument has an invalid value:

    >>> a, b, c = 1, 2
    Traceback (most recent call last):
    ValueError: not enough values to unpack (expected 3, got 2)

    >>> a, b = 1, 2, 3
    Traceback (most recent call last):
    ValueError: too many values to unpack (expected 2)

    >>> float('one')
    Traceback (most recent call last):
    ValueError: could not convert string to float: 'one'

    >>> int('one')
    Traceback (most recent call last):
    ValueError: invalid literal for int() with base 10: 'one'


Exception Hierarchy
-------------------
.. code-block:: text

    BaseException
     +-- SystemExit
     +-- KeyboardInterrupt
     +-- GeneratorExit
     +-- Exception
          +-- StopIteration
          +-- StopAsyncIteration
          +-- ArithmeticError
          |    +-- FloatingPointError
          |    +-- OverflowError
          |    +-- ZeroDivisionError
          +-- AssertionError
          +-- AttributeError
          +-- BufferError
          +-- EOFError
          +-- ImportError
          +-- LookupError
          |    +-- IndexError
          |    +-- KeyError
          +-- MemoryError
          +-- NameError
          |    +-- UnboundLocalError
          +-- OSError
          |    +-- BlockingIOError
          |    +-- ChildProcessError
          |    +-- ConnectionError
          |    |    +-- BrokenPipeError
          |    |    +-- ConnectionAbortedError
          |    |    +-- ConnectionRefusedError
          |    |    +-- ConnectionResetError
          |    +-- FileExistsError
          |    +-- FileNotFoundError
          |    +-- InterruptedError
          |    +-- IsADirectoryError
          |    +-- NotADirectoryError
          |    +-- PermissionError
          |    +-- ProcessLookupError
          |    +-- TimeoutError
          +-- ReferenceError
          +-- RuntimeError
          |    +-- NotImplementedError
          |    +-- RecursionError
          +-- SyntaxError
          |    +-- IndentationError
          |         +-- TabError
          +-- SystemError
          +-- TypeError
          +-- ValueError
          |    +-- UnicodeError
          |         +-- UnicodeDecodeError
          |         +-- UnicodeEncodeError
          |         +-- UnicodeTranslateError
          +-- Warning
               +-- DeprecationWarning
               +-- PendingDeprecationWarning
               +-- RuntimeWarning
               +-- SyntaxWarning
               +-- UserWarning
               +-- FutureWarning
               +-- ImportWarning
               +-- UnicodeWarning
               +-- BytesWarning
               +-- ResourceWarning


Raising Exceptions
------------------
Raise Exception without message:

    >>> raise RuntimeError
    Traceback (most recent call last):
    RuntimeError

Exception with additional message:

    >>> raise RuntimeError('Some message')
    Traceback (most recent call last):
    RuntimeError: Some message


Use Case
--------
    >>> input = lambda _: -10  # Assume user will input -10
    >>>
    >>> temperature = input('Type temperature [Kelvin]: ')
    >>>
    >>> if float(temperature) < 0:
    ...    raise ValueError('Kelvin temperature cannot be negative')
    Traceback (most recent call last):
    ValueError: Kelvin temperature cannot be negative

    >>> def convert(temperature):
    ...    if type(temperature) not in {float, int}:
    ...        raise TypeError('Temperature must be int or float')
    ...    if temperature < 0:
    ...        raise ValueError('Kelvin temperature cannot be negative')
    ...    return temperature

    >>> def apollo13():
    ...    raise RuntimeError('Oxygen tank explosion')
    >>>
    >>>
    >>> apollo13()
    Traceback (most recent call last):
    RuntimeError: Oxygen tank explosion

    >>> def apollo18():
    ...    raise NotImplementedError('Mission dropped due to budget cuts')
    >>>
    >>>
    >>> apollo18()
    Traceback (most recent call last):
    NotImplementedError: Mission dropped due to budget cuts


Assertion
---------
* Raises ``AssertionError`` if argument is ``False``
* Can have optional message
* Running Python with the ``-O`` optimization flag disables assert statements

    >>> data = [1, 2, 3]
    >>> assert type(data) is list
    >>> assert all(type(x) is int for x in data)

    >>> data = ('a', 'b', 'c')
    >>> assert type(data) is list
    Traceback (most recent call last):
    AssertionError
    >>> assert all(type(x) is int for x in data)
    Traceback (most recent call last):
    AssertionError

    >>> import sys
    >>> assert sys.version_info >= (3, 9)
    >>> assert sys.version_info >= (3, 9), 'Python 3.9+ required'


Traceback Analysis
------------------
* Stacktrace is 8 levels deep, it's not Java's 200 ;)

    >>> raise RuntimeError
    Traceback (most recent call last):
      File "<stdin>", line 1, in <module>
    RuntimeError

    >>> raise RuntimeError('Huston we have a problem')
    Traceback (most recent call last):
      File "<stdin>", line 1, in <module>
    RuntimeError: Huston we have a problem

    >>> def apollo13():
    ...    raise RuntimeError('Oxygen tank explosion')
    >>>
    >>>
    >>> apollo13()
    Traceback (most recent call last):
      File "<stdin>", line 1, in <module>
      File "<stdin>", line 2, in apollo13
    RuntimeError: Oxygen tank explosion

    >>> def apollo13():
    ...    raise RuntimeError('Oxygen tank explosion')
    >>>
    >>>
    >>> apollo13()
    Traceback (most recent call last):
      File "/home/watney/myscript.py", line 4, in <module>
        apollo13()
      File "/home/watney/myscript.py", line 2, in apollo13
        raise RuntimeError('Oxygen tank explosion')
    RuntimeError: Oxygen tank explosion

    >>> def apollo13():
    ...    raise RuntimeError('Oxygen tank explosion')
    >>>
    >>>
    >>> apollo13()
    Traceback (most recent call last):
      File "<input>", line 1, in <module>
      File "/Applications/PyCharm 2019.2 EAP.app/Contents/helpers/pydev/_pydev_bundle/pydev_umd.py", line 197, in runfile
        pydev_imports.execfile(filename, global_vars, local_vars)  # execute the script
      File "/Applications/PyCharm 2019.2 EAP.app/Contents/helpers/pydev/_pydev_imps/_pydev_execfile.py", line 18, in execfile
        exec(compile(contents+"\n", file, 'exec'), glob, loc)
      File "/home/watney/myscript.py", line 4, in <module>
        apollo13()
      File "/home/watney/myscript.py", line 2, in apollo13
        raise RuntimeError('Oxygen tank explosion')
    RuntimeError: Oxygen tank explosion


Change Verbosity Level
----------------------
* Change level with ``sys.tracebacklimit``
* From time to time you can have problems somewhere in the middle, but it's rare
* Last lines are the most important, in most cases error is there

    >>> import sys
    >>> sys.tracebacklimit = 2
    >>>
    >>>
    >>> def apollo13():
    ...    raise RuntimeError('Oxygen tank explosion')
    >>>
    >>> apollo13()
    Traceback (most recent call last):
      File "/home/watney/myscript.py", line 4, in <module>
        apollo13()
      File "/home/watney/myscript.py", line 2, in apollo13
        raise RuntimeError('Oxygen tank explosion')
    RuntimeError: Oxygen tank explosion


Catching Exceptions
-------------------
* ``try``
* ``except``
* ``else``
* ``finally``
* ``try`` is required and then one of the others blocks

    >>> try:
    ...     # try to execute
    ...     pass
    ... except Exception:
    ...     # what to do if exception occurs
    ...     pass
    ... else:
    ...     # what to do if no exception occurs
    ...     pass
    ... finally:
    ...     # What to do either if exception occurs or not
    ...     pass

Catch single exception:

    >>> def apollo13():
    ...    raise RuntimeError('Oxygen tank explosion')
    >>>
    >>>
    >>> try:
    ...     apollo13()
    ... except RuntimeError:
    ...     print('Houston we have a problem')
    Houston we have a problem

Catch many exceptions with the same handling:

    >>> def apollo13():
    ...    raise RuntimeError('Oxygen tank explosion')
    >>>
    >>>
    >>> try:
    ...     apollo13()
    ... except (RuntimeError, TypeError, NameError):
    ...     print('Houston we have a problem')
    Houston we have a problem

Catch many exceptions with different handling:

    >>> try:
    ...    with open(r'/tmp/my-file.txt') as file:
    ...         print(file.read())
    ... except FileNotFoundError:
    ...     print('File does not exist')
    ... except PermissionError:
    ...     print('Permission denied')
    File does not exist

Exceptions logging:

    >>> import logging
    >>>
    >>>
    >>> def apollo13():
    ...     raise RuntimeError('Oxygen tank explosion')
    >>>
    >>> try:
    ...     apollo13()
    ... except RuntimeError as err:
    ...     logging.error(err)
    ... #stderr: ERROR:root:Oxygen tank explosion


Else and Finally
----------------
* ``else`` is executed when no exception occurred
* ``finally`` is executed always (even if there was exception)
* Used to close file, connection or transaction to database

    >>> try:
    ...     file = open('/tmp/myfile.txt')
    ... except Exception:
    ...     print('Error, file cannot be open')
    ... else:
    ...     file.close()
    Error, file cannot be open

``else`` is executed when no exception occurred:

    >>> def apollo11():
    ...     print('Try landing on the Moon')
    >>>
    >>> try:
    ...     apollo11()
    ... except Exception:
    ...     print('Abort')
    ... else:
    ...     print('Landing a man on the Moon')
    Try landing on the Moon
    Landing a man on the Moon

``finally`` is executed always (even if there was exception):

    >>> def apollo11():
    ...    print('Try landing on the Moon')
    >>>
    >>> try:
    ...    apollo11()
    ... except Exception:
    ...    print('Abort')
    ... finally:
    ...    print('Returning safely to the Earth')
    Try landing on the Moon
    Returning safely to the Earth

    >>> def apollo11():
    ...    print('Program P63 - Landing Manoeuvre Approach Phase')
    ...    raise RuntimeError('1201 Alarm')
    ...    raise RuntimeError('1202 Alarm')
    ...    print('Contact lights')
    ...    print('The Eagle has landed!')
    ...    print("That's one small step for [a] man, one giant leap for mankind.")
    >>>
    >>> try:
    ...     apollo11()
    ... except RuntimeError:
    ...     print("You're GO for landing")
    ... except Exception:
    ...     print('Abort')
    ... else:
    ...     print('Landing a man on the Moon')
    ... finally:
    ...     print('Returning safely to the Earth')
    Program P63 - Landing Manoeuvre Approach Phase
    You're GO for landing
    Returning safely to the Earth


Pokemon Exception Handling
--------------------------
* "Gotta catch 'em all"
* ``Ctrl-C`` raises ``KeyboardInterrupt``

User cannot simply kill program with ``Ctrl-C``:

    >>> # doctest: +SKIP
    ... while True:
    ...    try:
    ...        number = float(input('Type number: '))
    ...    except:
    ...        continue

User can kill program with ``Ctrl-C``:

    >>> # doctest: +SKIP
    ... while True:
    ...     try:
    ...         number = float(input('Type number: '))
    ...     except Exception:
    ...         continue


Defining Own Exceptions
-----------------------
* class which inherits from ``Exception``

    >>> class MyError(Exception):
    ...    pass
    >>>
    >>>
    >>> raise MyError
    Traceback (most recent call last):
    MyError
    >>>
    >>> raise MyError('More verbose description')
    Traceback (most recent call last):
    MyError: More verbose description

Django Framework Use-case of Custom Exceptions:

    >>> # doctest: +SKIP
    ... from django.contrib.auth.models import User
    >>>
    >>>
    >>> def login(request):
    ...    username = request.POST.get('username')
    ...    password = request.POST.get('password')
    ...
    ...    try:
    ...        user = User.objects.get(username, password)
    ...    except User.DoesNotExist:
    ...        print('Sorry, no such user in database')

Django Framework Use-case of Custom Exceptions:

    >>> class Dragon:
    ...    def take_damage(self, damage):
    ...        raise self.IsDead
    ...
    ...    class IsDead(Exception):
    ...        pass
    >>>
    >>>
    >>> wawelski = Dragon()
    >>>
    >>> try:
    ...     wawelski.take_damage(10)
    ... except Dragon.IsDead:
    ...     print('Dragon is dead')
    Dragon is dead


Exit Status Code
----------------
* exit status ``0`` - no error
* any other exit status - error
* This will not work in Jupyter

    >>> try:
    ...     float('hello')
    ... except ValueError:
    ...     print('Cannot type cast to float')
    ...     exit(1)
    Traceback (most recent call last):
    SystemExit: 1

.. code-block:: console

    $ python3.9 -m doctest myscript.py
    $ echo $?
    0

.. code-block:: console

    $ python3.9 -m doctest myscript.py
    **********************************************************************
    File "/home/watney/myscript.py", line 41, in myscript
    Failed example:
        1 + 2
    Expected:
        3
    Got:
        4
    **********************************************************************
    1 items had failures:
       1 of   2 in myscript
    ***Test Failed*** 1 failures.

    $ echo $?
    1


Assignments
-----------
.. literalinclude:: assignments/controlflow_exception_a.py
    :caption: :download:`Solution <assignments/controlflow_exception_a.py>`
    :end-before: # Solution

.. literalinclude:: assignments/controlflow_exception_b.py
    :caption: :download:`Solution <assignments/controlflow_exception_b.py>`
    :end-before: # Solution

.. literalinclude:: assignments/controlflow_exception_c.py
    :caption: :download:`Solution <assignments/controlflow_exception_c.py>`
    :end-before: # Solution

.. literalinclude:: assignments/controlflow_exception_d.py
    :caption: :download:`Solution <assignments/controlflow_exception_d.py>`
    :end-before: # Solution

.. literalinclude:: assignments/controlflow_exception_e.py
    :caption: :download:`Solution <assignments/controlflow_exception_e.py>`
    :end-before: # Solution

.. literalinclude:: assignments/controlflow_exception_f.py
    :caption: :download:`Solution <assignments/controlflow_exception_f.py>`
    :end-before: # Solution

.. literalinclude:: assignments/controlflow_exception_g.py
    :caption: :download:`Solution <assignments/controlflow_exception_g.py>`
    :end-before: # Solution
